<?xml version="1.0" encoding="utf-8"?>
<!-- =================================================================================== -->
<!-- |    This document was autogenerated by xacro from magneto_2_bones.xacro          | -->
<!-- |    EDITING THIS FILE BY HAND IS NOT RECOMMENDED                                 | -->
<!-- =================================================================================== -->
<robot name="magneto">
<!-- Setup material colours for viewing in RViz -->
<material name="white">
  <color rgba="1 1 1 1"/>
</material>
<material name="blue">
  <color rgba="0 0 1 1"/>
</material>
<material name="green">
  <color rgba="0 1 0 1"/>
</material>
<material name="red">
  <color rgba="1 0 0 1"/>
</material>
<material name="black">
  <color rgba="0 0 0 0.9"/>
</material>
<material name="darkgrey">
  <color rgba="0.1 0.1 0.1 1"/>
</material>
<material name="midgrey">
  <color rgba="0.2 0.2 0.2 1"/>
</material>
<!-- =================================================================================== -->
<!-- |    virtual Joint (6 DoFs)                                                       | -->
<!-- =================================================================================== -->
<link name="world">
    <inertial>
      <origin xyz="0 0 0" rpy="0 0 0" />
      <mass value="0.00000001" />
      <inertia ixx="0.00000001" ixy="0.00000001" ixz="0.00000001" iyy="0.00000001" iyz="0.00000001" izz="0.00000001" />
    </inertial>
  </link>

  <link name="basePosX">
    <inertial>
      <origin xyz="0 0 0" rpy="0 0 0" />
      <mass value="0.00000001" />
      <inertia ixx="0.00000001" ixy="0.00000001" ixz="0.00000001" iyy="0.00000001" iyz="0.00000001" izz="0.00000001" />
    </inertial>
  </link>
  <joint name="basePosX" type="prismatic">
    <origin xyz="0 0 0" rpy="0 0 0" />
    <parent link="world" />
    <child link="basePosX" />
    <axis xyz="1 0 0" />
    <limit effort="200.0" velocity="100.0" lower="-200." upper="200." />
  </joint>

  <link name="basePosY">
    <inertial>
      <origin xyz="0 0 0" rpy="0 0 0" />
      <mass value="0.00000001" />
      <inertia ixx="0.00000001" ixy="0.00000001" ixz="0.00000001" iyy="0.00000001" iyz="0.00000001" izz="0.00000001" />
    </inertial>
  </link>
  <joint name="basePosY" type="prismatic">
    <origin xyz="0 0 0" rpy="0 0 0" />
    <parent link="basePosX" />
    <child link="basePosY" />
    <axis xyz="0 1 0" />
    <limit effort="200.0" velocity="100.0" lower="-200." upper="200." />
  </joint>

  <link name="basePosZ">
    <inertial>
      <origin xyz="0 0 0" rpy="0 0 0" />
      <mass value="0.00000001" />
      <inertia ixx="0.00000001" ixy="0.00000001" ixz="0.00000001" iyy="0.00000001" iyz="0.00000001" izz="0.00000001" />
    </inertial>
  </link>
  <joint name="basePosZ" type="prismatic">
    <origin xyz="0 0 0" rpy="0 0 0" />
    <parent link="basePosY" />
    <child link="basePosZ" />
    <axis xyz="0 0 1" />
    <limit effort="200.0" velocity="100.0" lower="-200." upper="200." />
  </joint>

  <link name="baseRotZ">
    <inertial>
      <origin xyz="0 0 0" rpy="0 0 0" />
      <mass value="0.00000001" />
      <inertia ixx="0.00000001" ixy="0.00000001" ixz="0.00000001" iyy="0.00000001" iyz="0.00000001" izz="0.00000001" />
    </inertial>
  </link>
  <joint name="baseRotZ" type="continuous">
    <origin xyz="0 0 0" rpy="0 0 0" />
    <parent link="basePosZ" />
    <child link="baseRotZ" />
    <axis xyz="0 0 1" />
  </joint>

  <link name="baseRotY">
    <inertial>
      <origin xyz="0 0 0" rpy="0 0 0" />
      <mass value="0.00000001" />
      <inertia ixx="0.00000001" ixy="0.00000001" ixz="0.00000001" iyy="0.00000001" iyz="0.00000001" izz="0.00000001" />
    </inertial>
  </link>
  <joint name="baseRotY" type="continuous">
    <origin xyz="0 0 0" rpy="0 0 0" />
    <parent link="baseRotZ" />
    <child link="baseRotY" />
    <axis xyz="0 1 0" />
  </joint>
  <!-- =================================================================================== -->
  <!-- =================================================================================== -->
  <link name="base_link">
    <inertial>
      <origin rpy="0 0 0" xyz="-0.2696E-03 0 33.3181E-03"/>
      <mass value="1.44521"/>
      <inertia ixx="0.0083421056972" ixy="-4.932e-08" ixz="-2.47500871e-05" iyy="0.0136724752281" iyz="2.37e-11" izz="0.0180888568473"/>
    </inertial>
    <visual>
      <geometry>
        <mesh filename="meshes//base_link.STL"/>
      </geometry>
      <origin rpy="0 0 0" xyz="0 0 0"/>
      <material name="midgrey"/>
    </visual>
    <collision>
      <geometry>
        <mesh filename="meshes//base_link_collision.STL"/>
      </geometry>
      <origin rpy="0 0 0" xyz="0 0 0"/>
    </collision>
  </link>
    <joint name="_base_joint" type="continuous">
    <parent link="baseRotY"/>
    <child link="base_link"/>
    <origin rpy="0 0 0" xyz="0 0 0"/>
    <axis xyz="1 0 0" />
  </joint>

  <link name="AR_coxa_link">
    <inertial>
      <origin rpy="0.0            0.0            0.0" xyz="0.0            0.0            0.0"/>
      <mass value="0.05629"/>
      <inertia ixx="6.383417e-05" ixy="0.0" ixz="0.0" iyy="2.843519e-05" iyz="0.0" izz="4.305331e-05"/>
    </inertial>
    <visual>
      <geometry>
        <mesh filename="meshes//coxa_link.STL"/>
      </geometry>
      <origin rpy="-1.5708          1.5708          0.0" xyz="0.0          0.0          0.0"/>
      <material name="darkgrey"/>
    </visual>
    <collision>
      <geometry>
        <mesh filename="meshes//coxa_link_collision.STL"/>
      </geometry>
      <origin rpy="-1.5708            1.5708            0.0" xyz="0.0            0.0            0.0"/>
    </collision>
  </link>
  <joint name="AR_coxa_joint" type="revolute">
    <limit effort="100.0" lower="-2.355" upper="2.355" velocity="5"/>
    <child link="AR_coxa_link"/>
    <parent link="base_link"/>
    <axis xyz="0 1 0"/>
    <origin rpy="1.5708 0 -0.785" xyz="0.124985156372 -0.0950142657006 0.0527"/>
  </joint>
  <link name="AR_femur_link">
    <inertial>
      <origin rpy="0.0            0.0            0.0" xyz="0.0331            0.0            0.00057"/>
      <mass value="0.25695"/>
      <inertia ixx="0.00023448195" ixy="8.961282e-05" ixz="2.299328e-05" iyy="0.00105768013" iyz="-8.2212e-07" izz="0.00113717868"/>
    </inertial>
    <visual>
      <geometry>
        <mesh filename="meshes//femur_link.STL"/>
      </geometry>
      <origin rpy="3.14159          0.0          0.0" xyz="0.0          0.0          0.0"/>
      <material name="darkgrey"/>
    </visual>
    <collision>
      <geometry>
        <mesh filename="meshes//femur_link_collision.STL"/>
      </geometry>
      <origin rpy="-1.5708            0.0            0.0" xyz="0.0            0.0            0.0"/>
    </collision>
  </link>
  <joint name="AR_femur_joint" type="revolute">
    <limit effort="100.0" lower="-1.571" upper="2.355" velocity="5"/>
    <child link="AR_femur_link"/>
    <parent link="AR_coxa_link"/>
    <axis xyz="0 0 1"/>
    <origin rpy="0 0 0" xyz="0 0.0393 0"/>
  </joint>
  <link name="AR_tibia_link">
    <inertial>
      <origin rpy="0.0            0.0            0.0" xyz="0.04813            0.0            0.00063"/>
      <mass value="0.57311"/>
      <inertia ixx="0.00012691396" ixy="-2.13598e-06" ixz="1.580716e-05" iyy="0.00135132424" iyz="4.859e-08" izz="0.00131598196"/>
    </inertial>
    <visual>
      <geometry>
        <mesh filename="meshes//tibia_link_ft.STL"/>
      </geometry>
      <origin rpy="0.0          0.0          0.0" xyz="0.0          0.0          0.0"/>
      <material name="black"/>
    </visual>
    <collision>
      <geometry>
        <mesh filename="meshes//tibia_link_ft.STL"/>
      </geometry>
      <origin rpy="0.0            0.0            0.0" xyz="0.0            0.0            0.0"/>
    </collision>
  </link>
  <joint name="AR_tibia_joint" type="revolute">
    <limit effort="100.0" lower="-2.355" upper="0.001" velocity="5"/>
    <child link="AR_tibia_link"/>
    <parent link="AR_femur_link"/>
    <axis xyz="0 0 1"/>
    <origin rpy="0.0 0 0.0" xyz="0.15 0 0"/>
  </joint>
  <link name="AR_foot_link_1">
    <inertial>
      <origin rpy="0 0 0" xyz="0.02E-03 2.88E-03 -4.39E-03"/>
      <mass value="0.03591"/>
      <inertia ixx="60131.00E-09" ixy="610.47E-09" ixz="387.97E-09" iyy="31108.13E-09" iyz="346.50E-09" izz="31112.38E-09"/>
    </inertial>
    <visual>
      <geometry>
        <mesh filename="meshes//foot_link_1.STL"/>
      </geometry>
      <origin rpy="0 0 0" xyz="0 0 0"/>
      <material name="black"/>
    </visual>
    <collision>
      <geometry>
        <mesh filename="meshes//foot_link_1_collision.STL"/>
      </geometry>
      <origin rpy="0 0 0" xyz="0 0 0"/>
    </collision>
  </link>
  <joint name="AR_foot_joint_1" type="revolute">
    <parent link="AR_tibia_link"/>
    <axis xyz="0 0 1"/>
    <origin rpy="0 0 0" xyz="0.132 0 0"/>
    <limit effort="100.0" lower="-0.523599" upper="0.523599" velocity="5"/>
    <child link="AR_foot_link_1"/>
    <dynamics damping="0.2" friction="0.0"/>
  </joint>
  <link name="AR_foot_link_2">
    <inertial>
      <origin rpy="0 0 0" xyz="0.02E-03 2.88E-03 -4.39E-03"/>
      <mass value="0.02961"/>
      <inertia ixx="8786.61E-09" ixy="34.74E-09" ixz="7.47E-09" iyy="10893.41E-09" iyz="-95.83E-09" izz="17608.23E-09"/>
    </inertial>
    <visual>
      <geometry>
        <mesh filename="meshes//foot_link_2.STL"/>
      </geometry>
      <origin rpy="0 0 0" xyz="0 0 0"/>
      <material name="black"/>
    </visual>
    <collision>
      <geometry>
        <mesh filename="meshes//foot_link_2_collision.STL"/>
      </geometry>
      <origin rpy="0 0 0" xyz="0 0 0"/>
    </collision>
  </link>
  <joint name="AR_foot_joint_2" type="revolute">
    <axis xyz="0 1 0"/>
    <limit effort="100.0" lower="-0.418879" upper="0.418879" velocity="5"/>
    <parent link="AR_foot_link_1"/>
    <child link="AR_foot_link_2"/>
    <origin rpy="0 0 0" xyz="0 0 0"/>
    <dynamics damping="0.2" friction="0.0"/>
  </joint>
  <link name="AR_foot_link_3">
    <inertial>
      <origin rpy="0 0 0" xyz="0.02E-03 2.88E-03 -4.39E-03"/>
      <mass value="0.32158"/>
      <inertia ixx="49836.99E-09" ixy="144.66E-09" ixz="-4031.72E-09" iyy="81967.91E-09" iyz="-678.12E-09" izz="69129.32E-09"/>
    </inertial>
    <visual>
      <geometry>
        <mesh filename="meshes//foot_link_3.STL"/>
      </geometry>
      <origin rpy="0 0 0" xyz="0 0 0"/>
      <material name="red"/>
    </visual>
    <collision>
      <geometry>
        <mesh filename="meshes//foot_link_3_collision.STL"/>
      </geometry>
      <origin rpy="0 0 0" xyz="0 0 0"/>
    </collision>
  </link>
  <joint name="AR_foot_joint_3" type="revolute">
    <axis xyz="1 0 0"/>
    <limit effort="100.0" lower="-2.07694" upper="2.07694" velocity="5"/>
    <parent link="AR_foot_link_2"/>
    <child link="AR_foot_link_3"/>
    <origin rpy="0 0 0" xyz="0 0 0"/>
    <dynamics damping="0.2" friction="0.0"/>
  </joint>
  <!-- =================================================================================== -->
  <link name="AR_foot_link">
    <inertial>
      <origin rpy="0 0 0" xyz="0 0 0" />
      <mass value="0.000001" />
      <inertia ixx="1E-9" ixy="1E-9" ixz="1E-9" iyy="1E-9" iyz="1E-9" izz="1E-9" />
    </inertial>
  </link>
  <joint name="AR_foot_joint" type="fixed">
    <parent link="AR_foot_link_3"/>
    <child link="AR_foot_link"/>
    <origin rpy="0 -1.5708 0" xyz="0.031 0 0"/>
  </joint>
  <!-- =================================================================================== -->
  <link name="BR_coxa_link">
    <inertial>
      <origin rpy="0.0            0.0            0.0" xyz="0.0            0.0            0.0"/>
      <mass value="0.05629"/>
      <inertia ixx="6.383417e-05" ixy="0.0" ixz="0.0" iyy="2.843519e-05" iyz="0.0" izz="4.305331e-05"/>
    </inertial>
    <visual>
      <geometry>
        <mesh filename="meshes//coxa_link.STL"/>
      </geometry>
      <origin rpy="-1.5708          1.5708          0.0" xyz="0.0          0.0          0.0"/>
      <material name="darkgrey"/>
    </visual>
    <collision>
      <geometry>
        <mesh filename="meshes//coxa_link_collision.STL"/>
      </geometry>
      <origin rpy="-1.5708            1.5708            0.0" xyz="0.0            0.0            0.0"/>
    </collision>
  </link>
  <joint name="BR_coxa_joint" type="revolute">
    <limit effort="100.0" lower="-2.355" upper="2.355" velocity="5"/>
    <child link="BR_coxa_link"/>
    <parent link="base_link"/>
    <axis xyz="0 1 0"/>
    <origin rpy="1.5708 0 -2.355" xyz="-0.12483367311 -0.0952132031704 0.0527"/>
  </joint>
  <link name="BR_femur_link">
    <inertial>
      <origin rpy="0.0            0.0            0.0" xyz="0.0331            0.0            0.00057"/>
      <mass value="0.25695"/>
      <inertia ixx="0.00023448195" ixy="8.961282e-05" ixz="2.299328e-05" iyy="0.00105768013" iyz="-8.2212e-07" izz="0.00113717868"/>
    </inertial>
    <visual>
      <geometry>
        <mesh filename="meshes//femur_link.STL"/>
      </geometry>
      <origin rpy="3.14159          0.0          0.0" xyz="0.0          0.0          0.0"/>
      <material name="darkgrey"/>
    </visual>
    <collision>
      <geometry>
        <mesh filename="meshes//femur_link_collision.STL"/>
      </geometry>
      <origin rpy="-1.5708            0.0            0.0" xyz="0.0            0.0            0.0"/>
    </collision>
  </link>
  <joint name="BR_femur_joint" type="revolute">
    <limit effort="100.0" lower="-1.571" upper="2.355" velocity="5"/>
    <child link="BR_femur_link"/>
    <parent link="BR_coxa_link"/>
    <axis xyz="0 0 1"/>
    <origin rpy="0 0 0" xyz="0 0.0393 0"/>
  </joint>
  <link name="BR_tibia_link">
    <inertial>
      <origin rpy="0.0            0.0            0.0" xyz="0.0363            0.0            -0.00011"/>
      <mass value="0.45311"/>
      <inertia ixx="8.692014e-05" ixy="-1.44653e-06" ixz="-3.73592e-06" iyy="0.00067791971" iyz="1.1736e-07" izz="0.00064913972"/>
    </inertial>
    <visual>
      <geometry>
        <mesh filename="meshes//tibia_link_no_ft.STL"/>
      </geometry>
      <origin rpy="0.0          0.0          0.0" xyz="0.0          0.0          0.0"/>
      <material name="black"/>
    </visual>
    <collision>
      <geometry>
        <mesh filename="meshes//tibia_link_no_ft.STL"/>
      </geometry>
      <origin rpy="0.0            0.0            0.0" xyz="0.0            0.0            0.0"/>
    </collision>
  </link>
  <joint name="BR_tibia_joint" type="revolute">
    <limit effort="100.0" lower="-2.355" upper="0.001" velocity="5"/>
    <child link="BR_tibia_link"/>
    <parent link="BR_femur_link"/>
    <axis xyz="0 0 1"/>
    <origin rpy="0.0 0 0.0" xyz="0.15 0 0"/>
  </joint>
  <link name="BR_foot_link_1">
    <inertial>
      <origin rpy="0 0 0" xyz="0.02E-03 2.88E-03 -4.39E-03"/>
      <mass value="0.03591"/>
      <inertia ixx="60131.00E-09" ixy="610.47E-09" ixz="387.97E-09" iyy="31108.13E-09" iyz="346.50E-09" izz="31112.38E-09"/>
    </inertial>
    <visual>
      <geometry>
        <mesh filename="meshes//foot_link_1.STL"/>
      </geometry>
      <origin rpy="0 0 0" xyz="0 0 0"/>
      <material name="black"/>
    </visual>
    <collision>
      <geometry>
        <mesh filename="meshes//foot_link_1_collision.STL"/>
      </geometry>
      <origin rpy="0 0 0" xyz="0 0 0"/>
    </collision>
  </link>
  <joint name="BR_foot_joint_1" type="revolute">
    <parent link="BR_tibia_link"/>
    <axis xyz="0 0 1"/>
    <origin rpy="0 0 0" xyz="0.132 0 0"/>
    <limit effort="100.0" lower="-0.523599" upper="0.523599" velocity="5"/>
    <child link="BR_foot_link_1"/>
    <dynamics damping="0.2" friction="0.0"/>
  </joint>
  <link name="BR_foot_link_2">
    <inertial>
      <origin rpy="0 0 0" xyz="0.02E-03 2.88E-03 -4.39E-03"/>
      <mass value="0.02961"/>
      <inertia ixx="8786.61E-09" ixy="34.74E-09" ixz="7.47E-09" iyy="10893.41E-09" iyz="-95.83E-09" izz="17608.23E-09"/>
    </inertial>
    <visual>
      <geometry>
        <mesh filename="meshes//foot_link_2.STL"/>
      </geometry>
      <origin rpy="0 0 0" xyz="0 0 0"/>
      <material name="black"/>
    </visual>
    <collision>
      <geometry>
        <mesh filename="meshes//foot_link_2_collision.STL"/>
      </geometry>
      <origin rpy="0 0 0" xyz="0 0 0"/>
    </collision>
  </link>
  <joint name="BR_foot_joint_2" type="revolute">
    <axis xyz="0 1 0"/>
    <limit effort="100.0" lower="-0.418879" upper="0.418879" velocity="5"/>
    <parent link="BR_foot_link_1"/>
    <child link="BR_foot_link_2"/>
    <origin rpy="0 0 0" xyz="0 0 0"/>
    <dynamics damping="0.2" friction="0.0"/>
  </joint>
  <link name="BR_foot_link_3">
    <inertial>
      <origin rpy="0 0 0" xyz="0.02E-03 2.88E-03 -4.39E-03"/>
      <mass value="0.32158"/>
      <inertia ixx="49836.99E-09" ixy="144.66E-09" ixz="-4031.72E-09" iyy="81967.91E-09" iyz="-678.12E-09" izz="69129.32E-09"/>
    </inertial>
    <visual>
      <geometry>
        <mesh filename="meshes//foot_link_3.STL"/>
      </geometry>
      <origin rpy="0 0 0" xyz="0 0 0"/>
      <material name="red"/>
    </visual>
    <collision>
      <geometry>
        <mesh filename="meshes//foot_link_3_collision.STL"/>
      </geometry>
      <origin rpy="0 0 0" xyz="0 0 0"/>
    </collision>
  </link>
  <joint name="BR_foot_joint_3" type="revolute">
    <axis xyz="1 0 0"/>
    <limit effort="100.0" lower="-2.07694" upper="2.07694" velocity="5"/>
    <parent link="BR_foot_link_2"/>
    <child link="BR_foot_link_3"/>
    <origin rpy="0 0 0" xyz="0 0 0"/>
    <dynamics damping="0.2" friction="0.0"/>
  </joint>
  <!-- =================================================================================== -->
  <link name="BR_foot_link">
    <inertial>
      <origin rpy="0 0 0" xyz="0 0 0" />
      <mass value="0.000001" />
      <inertia ixx="1E-9" ixy="1E-9" ixz="1E-9" iyy="1E-9" iyz="1E-9" izz="1E-9" />
    </inertial>
  </link>
  <joint name="BR_foot_joint" type="fixed">
    <parent link="BR_foot_link_3"/>
    <child link="BR_foot_link"/>
    <origin rpy="0 -1.5708 0" xyz="0.031 0 0"/>
  </joint>
  <!-- =================================================================================== -->
  <link name="BL_coxa_link">
    <inertial>
      <origin rpy="0.0            0.0            0.0" xyz="0.0            0.0            0.0"/>
      <mass value="0.05629"/>
      <inertia ixx="6.383417e-05" ixy="0.0" ixz="0.0" iyy="2.843519e-05" iyz="0.0" izz="4.305331e-05"/>
    </inertial>
    <visual>
      <geometry>
        <mesh filename="meshes//coxa_link.STL"/>
      </geometry>
      <origin rpy="-1.5708          1.5708          0.0" xyz="0.0          0.0          0.0"/>
      <material name="darkgrey"/>
    </visual>
    <collision>
      <geometry>
        <mesh filename="meshes//coxa_link_collision.STL"/>
      </geometry>
      <origin rpy="-1.5708            1.5708            0.0" xyz="0.0            0.0            0.0"/>
    </collision>
  </link>
  <joint name="BL_coxa_joint" type="revolute">
    <limit effort="100.0" lower="-2.355" upper="2.355" velocity="5"/>
    <child link="BL_coxa_link"/>
    <parent link="base_link"/>
    <axis xyz="0 1 0"/>
    <origin rpy="1.5708 0 2.355" xyz="-0.12483367311 0.0952132031704 0.0527"/>
  </joint>
  <link name="BL_femur_link">
    <inertial>
      <origin rpy="0.0            0.0            0.0" xyz="0.0331            0.0            0.00057"/>
      <mass value="0.25695"/>
      <inertia ixx="0.00023448195" ixy="8.961282e-05" ixz="2.299328e-05" iyy="0.00105768013" iyz="-8.2212e-07" izz="0.00113717868"/>
    </inertial>
    <visual>
      <geometry>
        <mesh filename="meshes//femur_link.STL"/>
      </geometry>
      <origin rpy="3.14159          0.0          0.0" xyz="0.0          0.0          0.0"/>
      <material name="darkgrey"/>
    </visual>
    <collision>
      <geometry>
        <mesh filename="meshes//femur_link_collision.STL"/>
      </geometry>
      <origin rpy="-1.5708            0.0            0.0" xyz="0.0            0.0            0.0"/>
    </collision>
  </link>
  <joint name="BL_femur_joint" type="revolute">
    <limit effort="100.0" lower="-1.571" upper="2.355" velocity="5"/>
    <child link="BL_femur_link"/>
    <parent link="BL_coxa_link"/>
    <axis xyz="0 0 1"/>
    <origin rpy="0 0 0" xyz="0 0.0393 0"/>
  </joint>
  <link name="BL_tibia_link">
    <inertial>
      <origin rpy="0.0            0.0            0.0" xyz="0.0363            0.0            -0.00011"/>
      <mass value="0.45311"/>
      <inertia ixx="8.692014e-05" ixy="-1.44653e-06" ixz="-3.73592e-06" iyy="0.00067791971" iyz="1.1736e-07" izz="0.00064913972"/>
    </inertial>
    <visual>
      <geometry>
        <mesh filename="meshes//tibia_link_no_ft.STL"/>
      </geometry>
      <origin rpy="0.0          0.0          0.0" xyz="0.0          0.0          0.0"/>
      <material name="black"/>
    </visual>
    <collision>
      <geometry>
        <mesh filename="meshes//tibia_link_no_ft.STL"/>
      </geometry>
      <origin rpy="0.0            0.0            0.0" xyz="0.0            0.0            0.0"/>
    </collision>
  </link>
  <joint name="BL_tibia_joint" type="revolute">
    <limit effort="100.0" lower="-2.355" upper="0.001" velocity="5"/>
    <child link="BL_tibia_link"/>
    <parent link="BL_femur_link"/>
    <axis xyz="0 0 1"/>
    <origin rpy="0.0 0 0.0" xyz="0.15 0 0"/>
  </joint>
  <link name="BL_foot_link_1">
    <inertial>
      <origin rpy="0 0 0" xyz="0.02E-03 2.88E-03 -4.39E-03"/>
      <mass value="0.03591"/>
      <inertia ixx="60131.00E-09" ixy="610.47E-09" ixz="387.97E-09" iyy="31108.13E-09" iyz="346.50E-09" izz="31112.38E-09"/>
    </inertial>
    <visual>
      <geometry>
        <mesh filename="meshes//foot_link_1.STL"/>
      </geometry>
      <origin rpy="0 0 0" xyz="0 0 0"/>
      <material name="black"/>
    </visual>
    <collision>
      <geometry>
        <mesh filename="meshes//foot_link_1_collision.STL"/>
      </geometry>
      <origin rpy="0 0 0" xyz="0 0 0"/>
    </collision>
  </link>
  <joint name="BL_foot_joint_1" type="revolute">
    <parent link="BL_tibia_link"/>
    <axis xyz="0 0 1"/>
    <origin rpy="0 0 0" xyz="0.132 0 0"/>
    <limit effort="100.0" lower="-0.523599" upper="0.523599" velocity="5"/>
    <child link="BL_foot_link_1"/>
    <dynamics damping="0.2" friction="0.0"/>
  </joint>
  <link name="BL_foot_link_2">
    <inertial>
      <origin rpy="0 0 0" xyz="0.02E-03 2.88E-03 -4.39E-03"/>
      <mass value="0.02961"/>
      <inertia ixx="8786.61E-09" ixy="34.74E-09" ixz="7.47E-09" iyy="10893.41E-09" iyz="-95.83E-09" izz="17608.23E-09"/>
    </inertial>
    <visual>
      <geometry>
        <mesh filename="meshes//foot_link_2.STL"/>
      </geometry>
      <origin rpy="0 0 0" xyz="0 0 0"/>
      <material name="black"/>
    </visual>
    <collision>
      <geometry>
        <mesh filename="meshes//foot_link_2_collision.STL"/>
      </geometry>
      <origin rpy="0 0 0" xyz="0 0 0"/>
    </collision>
  </link>
  <joint name="BL_foot_joint_2" type="revolute">
    <axis xyz="0 1 0"/>
    <limit effort="100.0" lower="-0.418879" upper="0.418879" velocity="5"/>
    <parent link="BL_foot_link_1"/>
    <child link="BL_foot_link_2"/>
    <origin rpy="0 0 0" xyz="0 0 0"/>
    <dynamics damping="0.2" friction="0.0"/>
  </joint>
  <link name="BL_foot_link_3">
    <inertial>
      <origin rpy="0 0 0" xyz="0.02E-03 2.88E-03 -4.39E-03"/>
      <mass value="0.32158"/>
      <inertia ixx="49836.99E-09" ixy="144.66E-09" ixz="-4031.72E-09" iyy="81967.91E-09" iyz="-678.12E-09" izz="69129.32E-09"/>
    </inertial>
    <visual>
      <geometry>
        <mesh filename="meshes//foot_link_3.STL"/>
      </geometry>
      <origin rpy="0 0 0" xyz="0 0 0"/>
      <material name="red"/>
    </visual>
    <collision>
      <geometry>
        <mesh filename="meshes//foot_link_3_collision.STL"/>
      </geometry>
      <origin rpy="0 0 0" xyz="0 0 0"/>
    </collision>
  </link>
  <joint name="BL_foot_joint_3" type="revolute">
    <axis xyz="1 0 0"/>
    <limit effort="100.0" lower="-2.07694" upper="2.07694" velocity="5"/>
    <parent link="BL_foot_link_2"/>
    <child link="BL_foot_link_3"/>
    <origin rpy="0 0 0" xyz="0 0 0"/>
    <dynamics damping="0.2" friction="0.0"/>
  </joint>
  <!-- =================================================================================== -->
  <link name="BL_foot_link">
    <inertial>
      <origin rpy="0 0 0" xyz="0 0 0" />
      <mass value="0.000001" />
      <inertia ixx="1E-9" ixy="1E-9" ixz="1E-9" iyy="1E-9" iyz="1E-9" izz="1E-9" />
    </inertial>
  </link>
  <joint name="BL_foot_joint" type="fixed">
    <parent link="BL_foot_link_3"/>
    <child link="BL_foot_link"/>
    <origin rpy="0 -1.5708 0" xyz="0.031 0 0"/>
  </joint>
  <!-- =================================================================================== -->
  <link name="AL_coxa_link">
    <inertial>
      <origin rpy="0.0            0.0            0.0" xyz="0.0            0.0            0.0"/>
      <mass value="0.05629"/>
      <inertia ixx="6.383417e-05" ixy="0.0" ixz="0.0" iyy="2.843519e-05" iyz="0.0" izz="4.305331e-05"/>
    </inertial>
    <visual>
      <geometry>
        <mesh filename="meshes//coxa_link.STL"/>
      </geometry>
      <origin rpy="-1.5708          1.5708          0.0" xyz="0.0          0.0          0.0"/>
      <material name="darkgrey"/>
    </visual>
    <collision>
      <geometry>
        <mesh filename="meshes//coxa_link_collision.STL"/>
      </geometry>
      <origin rpy="-1.5708            1.5708            0.0" xyz="0.0            0.0            0.0"/>
    </collision>
  </link>
  <joint name="AL_coxa_joint" type="revolute">
    <limit effort="100.0" lower="-2.355" upper="2.355" velocity="5"/>
    <child link="AL_coxa_link"/>
    <parent link="base_link"/>
    <axis xyz="0 1 0"/>
    <origin rpy="1.5708 0 0.785" xyz="0.124985156372 0.0950142657006 0.0527"/>
  </joint>
  <link name="AL_femur_link">
    <inertial>
      <origin rpy="0.0            0.0            0.0" xyz="0.0331            0.0            0.00057"/>
      <mass value="0.25695"/>
      <inertia ixx="0.00023448195" ixy="8.961282e-05" ixz="2.299328e-05" iyy="0.00105768013" iyz="-8.2212e-07" izz="0.00113717868"/>
    </inertial>
    <visual>
      <geometry>
        <mesh filename="meshes//femur_link.STL"/>
      </geometry>
      <origin rpy="3.14159          0.0          0.0" xyz="0.0          0.0          0.0"/>
      <material name="darkgrey"/>
    </visual>
    <collision>
      <geometry>
        <mesh filename="meshes//femur_link_collision.STL"/>
      </geometry>
      <origin rpy="-1.5708            0.0            0.0" xyz="0.0            0.0            0.0"/>
    </collision>
  </link>
  <joint name="AL_femur_joint" type="revolute">
    <limit effort="100.0" lower="-1.571" upper="2.355" velocity="5"/>
    <child link="AL_femur_link"/>
    <parent link="AL_coxa_link"/>
    <axis xyz="0 0 1"/>
    <origin rpy="0 0 0" xyz="0 0.0393 0"/>
  </joint>
  <link name="AL_tibia_link">
    <inertial>
      <origin rpy="0.0            0.0            0.0" xyz="0.0363            0.0            -0.00011"/>
      <mass value="0.45311"/>
      <inertia ixx="8.692014e-05" ixy="-1.44653e-06" ixz="-3.73592e-06" iyy="0.00067791971" iyz="1.1736e-07" izz="0.00064913972"/>
    </inertial>
    <visual>
      <geometry>
        <mesh filename="meshes//tibia_link_no_ft.STL"/>
      </geometry>
      <origin rpy="0.0          0.0          0.0" xyz="0.0          0.0          0.0"/>
      <material name="black"/>
    </visual>
    <collision>
      <geometry>
        <mesh filename="meshes//tibia_link_no_ft.STL"/>
      </geometry>
      <origin rpy="0.0            0.0            0.0" xyz="0.0            0.0            0.0"/>
    </collision>
  </link>
  <joint name="AL_tibia_joint" type="revolute">
    <limit effort="100.0" lower="-2.355" upper="0.001" velocity="5"/>
    <child link="AL_tibia_link"/>
    <parent link="AL_femur_link"/>
    <axis xyz="0 0 1"/>
    <origin rpy="0.0 0 0.0" xyz="0.15 0 0"/>
  </joint>
  <link name="AL_foot_link_1">
    <inertial>
      <origin rpy="0 0 0" xyz="0.02E-03 2.88E-03 -4.39E-03"/>
      <mass value="0.03591"/>
      <inertia ixx="60131.00E-09" ixy="610.47E-09" ixz="387.97E-09" iyy="31108.13E-09" iyz="346.50E-09" izz="31112.38E-09"/>
    </inertial>
    <visual>
      <geometry>
        <mesh filename="meshes//foot_link_1.STL"/>
      </geometry>
      <origin rpy="0 0 0" xyz="0 0 0"/>
      <material name="black"/>
    </visual>
    <collision>
      <geometry>
        <mesh filename="meshes//foot_link_1_collision.STL"/>
      </geometry>
      <origin rpy="0 0 0" xyz="0 0 0"/>
    </collision>
  </link>
  <joint name="AL_foot_joint_1" type="revolute">
    <parent link="AL_tibia_link"/>
    <axis xyz="0 0 1"/>
    <origin rpy="0 0 0" xyz="0.132 0 0"/>
    <limit effort="100.0" lower="-0.523599" upper="0.523599" velocity="5"/>
    <child link="AL_foot_link_1"/>
    <dynamics damping="0.2" friction="0.0"/>
  </joint>
  <link name="AL_foot_link_2">
    <inertial>
      <origin rpy="0 0 0" xyz="0.02E-03 2.88E-03 -4.39E-03"/>
      <mass value="0.02961"/>
      <inertia ixx="8786.61E-09" ixy="34.74E-09" ixz="7.47E-09" iyy="10893.41E-09" iyz="-95.83E-09" izz="17608.23E-09"/>
    </inertial>
    <visual>
      <geometry>
        <mesh filename="meshes//foot_link_2.STL"/>
      </geometry>
      <origin rpy="0 0 0" xyz="0 0 0"/>
      <material name="black"/>
    </visual>
    <collision>
      <geometry>
        <mesh filename="meshes//foot_link_2_collision.STL"/>
      </geometry>
      <origin rpy="0 0 0" xyz="0 0 0"/>
    </collision>
  </link>
  <joint name="AL_foot_joint_2" type="revolute">
    <axis xyz="0 1 0"/>
    <limit effort="100.0" lower="-0.418879" upper="0.418879" velocity="5"/>
    <parent link="AL_foot_link_1"/>
    <child link="AL_foot_link_2"/>
    <origin rpy="0 0 0" xyz="0 0 0"/>
    <dynamics damping="0.2" friction="0.0"/>
  </joint>
  <link name="AL_foot_link_3">
    <inertial>
      <origin rpy="0 0 0" xyz="0.02E-03 2.88E-03 -4.39E-03"/>
      <mass value="0.32158"/>
      <inertia ixx="49836.99E-09" ixy="144.66E-09" ixz="-4031.72E-09" iyy="81967.91E-09" iyz="-678.12E-09" izz="69129.32E-09"/>
    </inertial>
    <visual>
      <geometry>
        <mesh filename="meshes//foot_link_3.STL"/>
      </geometry>
      <origin rpy="0 0 0" xyz="0 0 0"/>
      <material name="red"/>
    </visual>
    <collision>
      <geometry>
        <mesh filename="meshes//foot_link_3_collision.STL"/>
      </geometry>
      <origin rpy="0 0 0" xyz="0 0 0"/>
    </collision>
  </link>
  <joint name="AL_foot_joint_3" type="revolute">
    <axis xyz="1 0 0"/>
    <limit effort="100.0" lower="-2.07694" upper="2.07694" velocity="5"/>
    <parent link="AL_foot_link_2"/>
    <child link="AL_foot_link_3"/>
    <origin rpy="0 0 0" xyz="0 0 0"/>
    <dynamics damping="0.2" friction="0.0"/>
  </joint>
  <!-- =================================================================================== -->
  <link name="AL_foot_link">
    <inertial>
      <origin rpy="0 0 0" xyz="0 0 0" />
      <mass value="0.000001" />
      <inertia ixx="1E-9" ixy="1E-9" ixz="1E-9" iyy="1E-9" iyz="1E-9" izz="1E-9" />
    </inertial>
  </link>
  <joint name="AL_foot_joint" type="fixed">
    <parent link="AL_foot_link_3"/>
    <child link="AL_foot_link"/>
    <origin rpy="0 -1.5708 0" xyz="0.031 0 0"/>
  </joint>
  <!-- =================================================================================== -->
</robot>

